Workbook
Name Categoria: 'Strutture ricettive'!$A$2:$A$1048576
Name Città: 'Strutture ricettive'!$D$2:$D$1048576
Name Denominazione: 'Strutture ricettive'!$B$2:$B$1048576
Name Indirizzo: 'Strutture ricettive'!$C$2:$C$1048576
Name Indirizzo_di_posta_elettronica: 'Strutture ricettive'!$G$2:$G$1048576
Name Indirizzo_internet: 'Strutture ricettive'!$F$2:$F$1048576
Name Localita: 'Strutture ricettive'!$E$2:$E$1048576
Name Nome_Struttura: '[1]Strutture ricettive'!$B$2:$B$1048576

Sheet Tabella1
D1: da controllare su query

Sheet Strutture ricettive
A1: Categoria | B1: Denominazione | C1: Indirizzo | D1: Città | E1: Localita | F1: Indirizzo internet | G1: Indirizzo di posta elettronica
A2: TURISMO RURALE | B2: COUNTRY HOUSE LOCALITA' GIROFALCO | C2: Via Girfalco, 26 | D2: URBINO | F2: www.girfalco.it | G2: info@girfalco.it
A3: ALTRI ALLOGGI PRIVATI | B3: STAGNOZZI STEFANIA | C3: Via Candigliano 5 | D3: ACQUALAGNA | E3: ACQUALAGNA | G3: gigliovitto@libero.it
A4: ALTRI ALLOGGI PRIVATI | B4: GORGOLINI ALESSANDRO | C4: Via San Gregorio 9 | D4: ACQUALAGNA | E4: ACQUALAGNA | G4: ale.gorgolini@gmail.com
A5: ALBERGHI | B5: LEON D'ORO | C5: Via Flaminia 213 | D5: ACQUALAGNA | E5: ACQUALAGNA
A6: ALBERGHI | B6: ALBERGO DOMUS MARIAE | C6: viale Ezio Scaglioni 17 | D6: ACQUALAGNA | E6: ACQUALAGNA | G6: giulianaspini@gmail.com
A7: ALTRI ALLOGGI PRIVATI | B7: TORRE COLOMBARA DI FRONTINO | C7: STRADA FRONTINO 24/B | D7: ACQUALAGNA | E7: ACQUALAGNA | G7: luccardi.sandro@gmail.com
A8: BED & BREAKFAST | B8: B&B AQUILEGIA | C8: via Furlo 12 | D8: ACQUALAGNA | E8: Furlo | F8: www.aquilegiabeb.com | G8: info@aquilegiabeb.com
A9: ALLOGGI AGRITURISTICI | B9: DEL FRONTINO | C9: strada frontino 23 | D9: ACQUALAGNA | E9: ACQUALAGNA
A10: ALBERGHI | B10: LA GINESTRA | C10: via Furlo 17 | D10: ACQUALAGNA | E10: ACQUALAGNA | F10: www.ginestrafurlo.it | G10: info@ginestrafurlo.it
A11: ALBERGHI | B11: BIRRA AL POZZO | C11: via Pianacce 12 | D11: ACQUALAGNA | E11: ACQUALAGNA | F11: www.birraalpozzo.it | G11: info@birraalpozzo.it
A12: BED & BREAKFAST | B12: B&B CRISTINI CRISTINA | C12: strada frontino 23 | D12: ACQUALAGNA | E12: ACQUALAGNA | G12: cri.cristini@alice.it
A13: BED & BREAKFAST | B13: B&B MARTELLONI CESARE | C13: via pianacce 67 | D13: ACQUALAGNA | E13: ACQUALAGNA | F13: www.lalocandadellabbazia.it | G13: info@lalocandadellabbazia.it
A14: ALBERGHI | B14: ALBERGO MEUBLE' SHINE | C14: via aldo gamba 54 | D14: ACQUALAGNA | E14: ACQUALAGNA
A15: ALLOGGI AGRITURISTICI | B15: AGRITURISMO CASTELLAGO | C15: strada Castellaro 18 | D15: ACQUALAGNA | E15: ACQUALAGNA | G15: castellago@virgilio.it
A16: ALBERGHI | B16: ALBERGO ANTICO FURLO | C16: via Flaminia 66 | D16: ACQUALAGNA | E16: ACQUALAGNA | F16: www.anticofurlo.it | G16: info@anticofurlo.it
A17: TURISMO RURALE | B17: CA' GARAVANO | C17: strada Frontino 21 | D17: ACQUALAGNA | E17: ACQUALAGNA | F17: www.cagaravano.com | G17: urbini.alessandro@alice.it
A18: ALTRI ALLOGGI PRIVATI | B18: IL CONIO DI DI GIOVANNI FEDERICO | C18: strada pietralatra 1 | D18: ACQUALAGNA | E18: ACQUALAGNA
A19: ALLOGGI AGRITURISTICI | B19: AGRITURISMO I CONTI | C19: via Pieve del Colle 11 b | D19: ACQUALAGNA | E19: pieve del colle | F19: www.agriturismoiconti.it | G19: info@agriturismoiconti.it
A20: ALLOGGI AGRITURISTICI | B20: LA COLOMBARA | C20: strada Frontino 24 | D20: ACQUALAGNA
A21: ALTRI ALLOGGI PRIVATI | B21: STROPPA GIUSEPPE | C21: strada San Gregorio 12 | D21: ACQUALAGNA | E21: Acqualagna | F21: http://lapanoramicadastroppa.webstarts.com/ | G21: stroppag@libero.it
A22: ALTRI ALLOGGI PRIVATI | B22: SERAFINI GIORGIA | D22: ACQUALAGNA
A23: ALTRI ALLOGGI PRIVATI | B23: BETTI VINCENZO | C23: via Pole 69 | D23: ACQUALAGNA
A24: ALLOGGI IN AFFITTO | B24: MARCHEHOLIDAY - CASALE DEGLI ULIVI | C24: strada San Gregorio 1 | D24: ACQUALAGNA | E24: loc.Ca Donnino | F24: www.marcheholiday.it/ulivi | G24: info@marcheholiday.it
A25: AREE DI SOSTA (PLEIN AIR) | B25: AREA SOSTA CAMPER PARCO LE QUERCE | C25: via Pianacce 1 | D25: ACQUALAGNA | E25: RISERVA NATURALE STATALE GOLA DEL FURLO | F25: parcodelfurlo.it | G25: info@parcodelfurlo.it
A26: ALTRI ALLOGGI PRIVATI | B26: BACCHIOCCHI MARIA ELISA | C26: via San Gregorio 17 | D26: ACQUALAGNA | G26: remigio.battistelli@gmail.com
A27: ALTRI ALLOGGI PRIVATI | B27: MARCHETTI LORENZA | C27: via Fossato 37/b | D27: ACQUALAGNA | G27: thomas.clementi@hotmail.it
A28: BED & BREAKFAST | B28: B&B BISCUBIO | C28: via Circonvallazione 46 | D28: APECCHIO | G28: marcellamartinelli17@gmail.com
A29: ALBERGHI | B29: GHIGHETTA | C29: via Borgo Mazzini 40 | D29: APECCHIO | G29: doradimaggio@libero.it
A30: ALLOGGI AGRITURISTICI | B30: AGRITURISMO LA ROCCA | D30: APECCHIO | E30: località la rocca | G30: a.parlani@alice.it
A31: ALLOGGI AGRITURISTICI | B31: AGRITURISMO CA' PIERPAOLI | D31: APECCHIO | E31: località Ca' Pierpaoli | F31: www.chipierpaoli.it | G31: info@chipierpaoli.it
A32: ALLOGGI AGRITURISTICI | B32: AGRITURISMO PIANDIMOLINO | C32: località Pian di Molino 16 | D32: APECCHIO | E32: PIAN DI MOLINO | F32: www.agriturismopiandimolino.it | G32: info@agriturismopiandimolino.it
A33: BED & BREAKFAST | B33: B&B GRANCI MARIA GRAZIA | C33: via Martiri della Liberta' 20 | D33: APECCHIO | E33: APECCHIO
A34: TURISMO RURALE | B34: LE CIOCCHE | D34: APECCHIO | E34: APECCHIO | G34: ale_cipi@live.it
A35: ALLOGGI AGRITURISTICI | B35: FONTE SOMMA | D35: APECCHIO | E35: loc.Fontesomma | F35: www.fontesomma.it | G35: info@fontesomma.it
A36: TURISMO RURALE | B36: COL ALPI | C36: via Circonvallazione 40 | D36: APECCHIO | E36: APECCHIO | G36: ilaesimo@virgilio.it
A37: TURISMO RURALE | B37: COUNTRY HOUSE CACCIABOCCA | C37: vocabolo Caselle 100 | D37: APECCHIO | E37: APECCHIO | F37: www.countryhousechiciabocca.it | G37: info@countryhousechiciabocca.it
A38: BED & BREAKFAST | B38: B&B MOCHI EDMONDO ADOLFO FEDERICO | C38: via dante alighieri 41 | D38: APECCHIO | E38: APECCHIO | G38: elenamochi@hotmail.it
A39: AREE DI SOSTA (PLEIN AIR) | B39: AREA DI SOSTA CAMPER | D39: APECCHIO | E39: APECCHIO
A40: ALLOGGI IN AFFITTO | B40: AFFITTACAMERE APPENNINO | C40: via Garibaldi 9 | D40: APECCHIO | G40: marcellamartinelli17@gmail.com
...

Sheet prezzi1

Sheet RICERCA (+es)
B1: Colonna1 | C1: Colonna2 | E1: Esercizio 4 | H1: Esercizio 5 | L1: Esercizio 16
L2: Città | M2: Numero strutture | N2: Prezzo medio | P2: Covarianza | Q2: =_xlfn.COVARIANCE.S(M3:M236,N3:N236) -> -52.023605
B3: RICERCA STRUTTURA | H3: ACQUALAGNA | L3: {=prezzi__2[CITTA'']} -> URBINO | M3: =COUNTIFS(Tabella1[Città],L2) -> 0 | N3: {=prezzi__2[PREZZO MEDIO]} -> 31 | P3: Correlazione | Q3: =CORREL(M3:M236,N3:N236) -> -0.037066971
L4: ACQUALAGNA | M4: =COUNTIFS(Tabella1[Città],L3) -> 144 | N4: 75 | P4: Il coefficiente di correlazione tra numero di strutture e prezzo medio è -0,037, un valore molto vicino allo 0. Questo significa che nonostante il senso negativo(una tendenza inversa), il legame tra le due variabiliè praticamente inesistente . La covarianza negativa conferma la stessa direzione debole, ma essendo il coefficiente di correlazione così vicino a 0, non si può parlare di una relazione rilevante tra le due variabili.
B5: NOME STRUTTURA | C5: ALEXANDER MUSEUM PALACE HOTEL | E5: BED & BREAKFAST | F5: 1809 | H5: ALBERGHI | I5: ALBERGO ANTICO FURLO | L5: APECCHIO | M5: =COUNTIFS(Tabella1[Città],L4) -> 25 | N5: 77
B6: CITTA' | C6: =IF(_xlfn.XLOOKUP(C5, Tabella1[Denominazione], Tabella1[Città], "")="", "Non disponibile", _xlfn.XLOOKUP(C5, Tabella1[Denominazione], Tabella1[Città], "Non disponibile")) -> PESARO | E6: STABILIMENTI BALNEARI | F6: 850 | H6: ALBERGHI | I6: ALBERGO DOMUS MARIAE | L6: AUDITORE | M6: =COUNTIFS(Tabella1[Città],L5) -> 31 | N6: 93 | P6: Esercizio 17
B7: INDIRIZZO | C7: =IF(_xlfn.XLOOKUP(C5, Tabella1[Denominazione], Tabella1[Indirizzo], "")="", "Non disponibile", _xlfn.XLOOKUP(C5, Tabella1[Denominazione], Tabella1[Indirizzo], "Non disponibile")) -> viale trieste 20 | E7: ALLOGGI AGRITURISTICI | F7: 830 | H7: ALBERGHI | I7: ALBERGO MEUBLE' SHINE | L7: BARCHI | M7: =COUNTIFS(Tabella1[Città],L6) -> 7 | N7: 83
B8: EMAIL | C8: =IF(_xlfn.XLOOKUP(C5, Tabella1[Denominazione], Tabella1[Indirizzo di posta elettronica], "")="", "Non disponibile", _xlfn.XLOOKUP(C5, Tabella1[Denominazione], Tabella1[Indirizzo di posta elettronica], "Non disponibile")) -> alexander@viphotels.it | E8: ALBERGHI | F8: 814 | H8: ALBERGHI | I8: BIRRA AL POZZO | L8: BELFORTE ALL'ISAURO | M8: =COUNTIFS(Tabella1[Città],L7) -> 8 | N8: 49
B9: INDIRIZZO WEB | C9: =IF(_xlfn.XLOOKUP(C5, Tabella1[Denominazione], Tabella1[Indirizzo internet], "")="", "Non disponibile", _xlfn.XLOOKUP(C5, Tabella1[Denominazione], Tabella1[Indirizzo internet], "Non disponibile")) -> www.alexandermuseum.it | E9: ALTRI ALLOGGI PRIVATI | F9: 721 | H9: ALBERGHI | I9: LA GINESTRA | L9: BORGO PACE | M9: =COUNTIFS(Tabella1[Città],L8) -> 3 | N9: 58
B10: Numero totale strutture | C10: =COUNTA(Tabella1[Denominazione]) -> 6258 | E10: ALLOGGI IN AFFITTO | F10: 541 | H10: ALBERGHI | I10: LEON D'ORO | L10: CAGLI | M10: =COUNTIFS(Tabella1[Città],L9) -> 15 | N10: 64
B11: Numero strutture per LOCALITA' | C11: =COUNTIFS(Tabella1[Localita],C6) -> 158 | E11: TURISMO RURALE | F11: 304 | H11: ALLOGGI AGRITURISTICI | I11: AGRITURISMO CASTELLAGO | L11: CANTIANO | M11: =COUNTIFS(Tabella1[Città],L10) -> 66 | N11: 106
E12: CAMPEGGI | F12: 93 | H12: ALLOGGI AGRITURISTICI | I12: AGRITURISMO I CONTI | L12: CARPEGNA | M12: =COUNTIFS(Tabella1[Città],L11) -> 11 | N12: 118
E13: AREE DI SOSTA (PLEIN AIR) | F13: 86 | H13: ALLOGGI AGRITURISTICI | I13: DEL FRONTINO | L13: CARTOCETO | M13: =COUNTIFS(Tabella1[Città],L12) -> 17 | N13: 36
E14: CASE PER FERIE | F14: 82 | H14: ALLOGGI AGRITURISTICI | I14: LA COLOMBARA | L14: FANO | M14: =COUNTIFS(Tabella1[Città],L13) -> 13 | N14: 120
E15: RESIDENZE TURISTICO ALBERGHIERE | F15: 52 | H15: ALLOGGI IN AFFITTO | I15: MARCHEHOLIDAY - CASALE DEGLI ULIVI | L15: FERMIGNANO | M15: =COUNTIFS(Tabella1[Città],L14) -> 333 | N15: 88
E16: OSTELLI PER LA GIOVENTU' | F16: 30 | H16: ALTRI ALLOGGI PRIVATI | I16: BACCHIOCCHI MARIA ELISA | L16: FOSSOMBRONE | M16: =COUNTIFS(Tabella1[Città],L15) -> 21 | N16: 66
E17: VILLAGGI TURISTICI | F17: 17 | H17: ALTRI ALLOGGI PRIVATI | I17: BETTI VINCENZO | L17: FRATTE ROSA | M17: =COUNTIFS(Tabella1[Città],L16) -> 20 | N17: 119
E18: RIFUGI | F18: 16 | H18: ALTRI ALLOGGI PRIVATI | I18: GORGOLINI ALESSANDRO | L18: FRONTINO | M18: =COUNTIFS(Tabella1[Città],L17) -> 4 | N18: 52
E19: ALTRI ESERCIZI RICETTIVI | F19: 13 | H19: ALTRI ALLOGGI PRIVATI | I19: IL CONIO DI DI GIOVANNI FEDERICO | L19: FRONTONE | M19: =COUNTIFS(Tabella1[Città],L18) -> 16 | N19: 75
H20: ALTRI ALLOGGI PRIVATI | I20: MARCHETTI LORENZA | L20: GABICCE MARE | M20: =COUNTIFS(Tabella1[Città],L19) -> 13 | N20: 112
H21: ALTRI ALLOGGI PRIVATI | I21: SERAFINI GIORGIA | L21: GRADARA | M21: =COUNTIFS(Tabella1[Città],L20) -> 178 | N21: 87
H22: ALTRI ALLOGGI PRIVATI | I22: STAGNOZZI STEFANIA | L22: ISOLA DEL PIANO | M22: =COUNTIFS(Tabella1[Città],L21) -> 28 | N22: 46
H23: ALTRI ALLOGGI PRIVATI | I23: STROPPA GIUSEPPE | L23: LUNANO | M23: =COUNTIFS(Tabella1[Città],L22) -> 6 | N23: 36
H24: ALTRI ALLOGGI PRIVATI | I24: TORRE COLOMBARA DI FRONTINO | L24: MACERATA FELTRIA | M24: =COUNTIFS(Tabella1[Città],L23) -> 2 | N24: 32
H25: AREE DI SOSTA (PLEIN AIR) | I25: AREA SOSTA CAMPER PARCO LE QUERCE | L25: MERCATELLO SUL METAURO | M25: =COUNTIFS(Tabella1[Città],L24) -> 9 | N25: 85
H26: BED & BREAKFAST | I26: B&B AQUILEGIA | L26: MERCATINO CONCA | M26: =COUNTIFS(Tabella1[Città],L25) -> 21 | N26: 120
H27: BED & BREAKFAST | I27: B&B CRISTINI CRISTINA | L27: MOMBAROCCIO | M27: =COUNTIFS(Tabella1[Città],L26) -> 2 | N27: 39
H28: BED & BREAKFAST | I28: B&B MARTELLONI CESARE | L28: MONDAVIO | M28: =COUNTIFS(Tabella1[Città],L27) -> 14 | N28: 116
H29: TURISMO RURALE | I29: CA' GARAVANO | L29: MONDOLFO | M29: =COUNTIFS(Tabella1[Città],L28) -> 13 | N29: 64
L30: MONTECALVO IN FOGLIA | M30: =COUNTIFS(Tabella1[Città],L29) -> 84 | N30: 46
L31: MONTE CERIGNONE | M31: =COUNTIFS(Tabella1[Città],L30) -> 7 | N31: 78
L32: MONTECICCARDO | M32: =COUNTIFS(Tabella1[Città],L31) -> 6 | N32: 48
L33: MONTECOPIOLO | M33: =COUNTIFS(Tabella1[Città],L32) -> 8 | N33: 51
L34: MONTEFELCINO | M34: =COUNTIFS(Tabella1[Città],L33) -> 10 | N34: 61
L35: MONTE GRIMANO TERME | M35: =COUNTIFS(Tabella1[Città],L34) -> 8 | N35: 107
L36: MONTELABBATE | M36: =COUNTIFS(Tabella1[Città],L35) -> 9 | N36: 49
L37: MONTEMAGGIORE AL METAURO | M37: =COUNTIFS(Tabella1[Città],L36) -> 6 | N37: 120
L38: MONTE PORZIO | M38: =COUNTIFS(Tabella1[Città],L37) -> 11 | N38: 119
L39: ORCIANO DI PESARO | M39: =COUNTIFS(Tabella1[Città],L38) -> 9 | N39: 85
L40: PEGLIO | M40: =COUNTIFS(Tabella1[Città],L39) -> 7 | N40: 109
...

Sheet Foglio4
A1: Esercizio 10
A2: Totale strutture: | C2: =COUNTA(Tabella1[Denominazione]) -> 6258
A3: Numero alberghi: | C3: =COUNTIFS(Tabella1[Categoria],"ALBERGHI") -> 814
A4: Numero B&B: | C4: =COUNTIFS(Tabella1[Categoria],"BED & BREAKFAST") -> 1809
A6: Probabilità che sia un albergo: | D6: =C3/C2 -> 0.13007351
A7: Probabilità che sia un B&B: | D7: =C4/C2 -> 0.28906999
A8: Probabilità che estraendone due indipendenti siano entrambi alberghi: | H8: =(C3/C2)^2 -> 0.016919117 | J8: I B&B sono la categoria più diffusa. La probabilità che due estrazioni indipendenti siano entrambe un albergo è molto bassa.
A11: Esercizio 11
A12: Intervallo +/-1 deviazione standard
A13: Lim. Inf. | B13: ='prezzi (2)'!G1-'prezzi (2)'!G6 -> 64
A14: Lim. Sup. | B14: ='prezzi (2)'!G1+'prezzi (2)'!G6 -> 83
A15: Intervallo +/-2 deviazione standard
A16: Lim inf. | B16: ='prezzi (2)'!G1-2*'prezzi (2)'!G6 -> 54.5
A17: Lim. Sup. | B17: ='prezzi (2)'!G1+2*'prezzi (2)'!G6 -> 92.5
A19: Esercizio 12
A20: Urbino | B20: =_xlfn.XLOOKUP(A20,prezzi__2[CITTA''], prezzi__2[PREZZO MEDIO],"Non trovata") -> 31 | C20: =(B20-'prezzi (2)'!G1)/'prezzi (2)'!G6 -> -4.4736842 | E20: La città scelta ha un prezzo di 31 euro, corrispondente ad uno z-score di -4,47, molto al di sotto della media (73,5euro). E' un valore piuttosto raro considerando che la maggior parte dei dati si trova entro due o tre deviazoni standard dalla media. La probabilità è vicinissima allo 0 il che conferma quanto sia improbabile trovare un prezzo cosi basso se i dati seguissero davvero una distribuzione normale perfetta.
C21: =_xlfn.NORM.S.DIST(C20,TRUE) -> 3.8441632e-06
A22: Esercizio 13
A23: Margine di errore | C23: =_xlfn.CONFIDENCE.NORM(0.05,_xlfn.STDEV.P('prezzi (2)'!B2:B235),COUNTA('prezzi (2)'!B2:B235)) -> 3.5183876
A24: Limiti dell intervallo:
C25: lim. Inf. | D25: ='prezzi (2)'!G1-Foglio4!C23 -> 69.981612 | F25: Il prezzo medio calcolato sul campione delle città è di 73,5€. Con un livello di confidenza del 95%, possiamo dire che il vero prezzo medio di tutte le città (la popolazione) è compreso tra 69€ e 77€. Questo significa che se ripetessimo il campionamento molte volte, il 95% degli intervalli conterebbe il vero valore medio della popolazione.
C26: lim. Sup. | D26: ='prezzi (2)'!G1+Foglio4!C23 -> 77.018388
A27: Esercizio 14
A28: Margini di errore | C28: AL 90% | D28: =_xlfn.CONFIDENCE.NORM(0.1,_xlfn.STDEV.P('prezzi (2)'!B2:B235),COUNTA('prezzi (2)'!B2:B235)) -> 2.9527239 | F28: Aumentando il livello di confidenza dal 90% al 99%, l'intervallo diventa più ampio:cresce il margine di errore da 2,9(90%), a 3,52(95%) fino a circa 4,6(99%). Ciò succede in quanto,per essere più sicuri di catturare il vero valore della popolazione, dobbiamo allargare l'intervallo di stima.
C29: AL 99% | D29: =_xlfn.CONFIDENCE.NORM(0.01,_xlfn.STDEV.P('prezzi (2)'!B2:B235),COUNTA('prezzi (2)'!B2:B235)) -> 4.6239451
F30: Se la numeriosità campionaria n quadruplicasse , il margine di errore si dimezzerebbe, poiché la formula del margine di errore è inversamente proporzionale alla radice quadrata di n.

Sheet prezzi (2)
A1: CITTA' | B1: PREZZO MEDIO | C1: OUTLIER | D1: AGRITURISMO | E1: ALBERGO | F1: MEDIA | G1: =AVERAGE(B2:B235) -> 73.5
A2: URBINO | B2: 31 | C2: =IF(OR(B2<$M$5,B2>$M$4),"OUTLIER"," ") | D2: =IF(COUNTIFS(Tabella1[Città], A2, Tabella1[Categoria],"ALLOGGI AGRITURISTICI")>0,"SI","NO") -> SI | E2: =IF(COUNTIFS(Tabella1[Città], A2, Tabella1[Categoria],"ALBERGHI")>0,"SI","NO") -> SI | F2: MEDIANA | G2: =MEDIAN(B2:B235,) -> 73 | I2: CLASSE PREZZO | J2: FREQUENZA | L2: Q1 | M2: =_xlfn.QUARTILE.INC(B2:B235,1) -> 50.25
A3: ACQUALAGNA | B3: 75 | C3: =IF(OR(B3<$M$5,B3>$M$4),"OUTLIER"," ") | D3: =IF(COUNTIFS(Tabella1[Città], A3, Tabella1[Categoria],"ALLOGGI AGRITURISTICI")>0,"SI","NO") -> SI | E3: =IF(COUNTIFS(Tabella1[Città], A3, Tabella1[Categoria],"ALBERGHI")>0,"SI","NO") -> SI | F3: MODA | G3: =MODE(B2:B235) -> 75 | I3: 0-20 | J3: =COUNTIFS(B2:B235,">=0",B2:B235,"<=20") -> 0 | L3: Q3 | M3: =_xlfn.QUARTILE.INC(B2:B235,3) -> 97
A4: APECCHIO | B4: 77 | C4: =IF(OR(B4<$M$5,B4>$M$4),"OUTLIER"," ") | D4: =IF(COUNTIFS(Tabella1[Città], A4, Tabella1[Categoria],"ALLOGGI AGRITURISTICI")>0,"SI","NO") -> SI | E4: =IF(COUNTIFS(Tabella1[Città], A4, Tabella1[Categoria],"ALBERGHI")>0,"SI","NO") -> SI | I4: 20-40 | J4: =COUNTIFS(B2:B235,">=20",B2:B235,"<=40") -> 37 | L4: LIM.SUP. | M4: =M3+1.5*(M3-M2) -> 167.125
A5: AUDITORE | B5: 93 | C5: =IF(OR(B5<$M$5,B5>$M$4),"OUTLIER"," ") | D5: =IF(COUNTIFS(Tabella1[Città], A5, Tabella1[Categoria],"ALLOGGI AGRITURISTICI")>0,"SI","NO") -> NO | E5: =IF(COUNTIFS(Tabella1[Città], A5, Tabella1[Categoria],"ALBERGHI")>0,"SI","NO") -> SI | F5: VARIANZA | G5: =_xlfn.VAR.P(B2,B235) -> 90.25 | I5: 40-60 | J5: =COUNTIFS(B2:B235,">=40",B2:B235,"<=60") -> 53 | L5: LIM.INF. | M5: =M2-1.5*(M3-M2) -> -19.875
A6: BARCHI | B6: 83 | C6: =IF(OR(B6<$M$5,B6>$M$4),"OUTLIER"," ") | D6: =IF(COUNTIFS(Tabella1[Città], A6, Tabella1[Categoria],"ALLOGGI AGRITURISTICI")>0,"SI","NO") -> SI | E6: =IF(COUNTIFS(Tabella1[Città], A6, Tabella1[Categoria],"ALBERGHI")>0,"SI","NO") -> NO | F6: DEV. STAN. | G6: =_xlfn.STDEV.P(B2,B235) -> 9.5 | I6: 60-80 | J6: =COUNTIFS(B2:B235,">=60",B2:B235,"<=80") -> 53
A7: BELFORTE ALL'ISAURO | B7: 49 | C7: =IF(OR(B7<$M$5,B7>$M$4),"OUTLIER"," ") | D7: =IF(COUNTIFS(Tabella1[Città], A7, Tabella1[Categoria],"ALLOGGI AGRITURISTICI")>0,"SI","NO") -> SI | E7: =IF(COUNTIFS(Tabella1[Città], A7, Tabella1[Categoria],"ALBERGHI")>0,"SI","NO") -> NO | F7: IQR. | G7: =_xlfn.QUARTILE.INC(B2:B235,3)-_xlfn.QUARTILE.INC(B2:B235,1) -> 46.75 | I7: 80-100 | J7: =COUNTIFS(B2:B235,">=80",B2:B235,"<=100") -> 41
A8: BORGO PACE | B8: 58 | C8: =IF(OR(B8<$M$5,B8>$M$4),"OUTLIER"," ") | D8: =IF(COUNTIFS(Tabella1[Città], A8, Tabella1[Categoria],"ALLOGGI AGRITURISTICI")>0,"SI","NO") -> SI | E8: =IF(COUNTIFS(Tabella1[Città], A8, Tabella1[Categoria],"ALBERGHI")>0,"SI","NO") -> SI | I8: 100-120 | J8: =COUNTIFS(B2:B235,">=100",B2:B235,"<=120") -> 57
A9: CAGLI | B9: 64 | C9: =IF(OR(B9<$M$5,B9>$M$4),"OUTLIER"," ") | D9: =IF(COUNTIFS(Tabella1[Città], A9, Tabella1[Categoria],"ALLOGGI AGRITURISTICI")>0,"SI","NO") -> SI | E9: =IF(COUNTIFS(Tabella1[Città], A9, Tabella1[Categoria],"ALBERGHI")>0,"SI","NO") -> SI | F9: La media e la mediana sono molto vicine tra di loro, perciò la distribuzione dei prezzi medi è per lo più simmetrica,senza una forte asimmetria verso valori alti o bassi. La moda è anch'essa vicina agli altri due indici, confermando che i prezzi si concentrano attorno al valore centrale. La deviazione standard indica una dispersione moderata dei prezzi attorno alla media, coerente con l'IQR di 46,75. | I9: 120-140 | J9: =COUNTIFS(B2:B235,">=120",B2:B235,"<=140") -> 5
A10: CANTIANO | B10: 106 | C10: =IF(OR(B10<$M$5,B10>$M$4),"OUTLIER"," ") | D10: =IF(COUNTIFS(Tabella1[Città], A10, Tabella1[Categoria],"ALLOGGI AGRITURISTICI")>0,"SI","NO") -> SI | E10: =IF(COUNTIFS(Tabella1[Città], A10, Tabella1[Categoria],"ALBERGHI")>0,"SI","NO") -> SI | I10: CLASSE MODALE | J10: =INDEX(I3:I9,MATCH(MAX(J3:J9),J3:J9,0)) -> 100-120
A11: CARPEGNA | B11: 118 | C11: =IF(OR(B11<$M$5,B11>$M$4),"OUTLIER"," ") | D11: =IF(COUNTIFS(Tabella1[Città], A11, Tabella1[Categoria],"ALLOGGI AGRITURISTICI")>0,"SI","NO") -> SI | E11: =IF(COUNTIFS(Tabella1[Città], A11, Tabella1[Categoria],"ALBERGHI")>0,"SI","NO") -> SI
A12: CARTOCETO | B12: 36 | C12: =IF(OR(B12<$M$5,B12>$M$4),"OUTLIER"," ") | D12: =IF(COUNTIFS(Tabella1[Città], A12, Tabella1[Categoria],"ALLOGGI AGRITURISTICI")>0,"SI","NO") -> SI | E12: =IF(COUNTIFS(Tabella1[Città], A12, Tabella1[Categoria],"ALBERGHI")>0,"SI","NO") -> NO | F12: Applicando la regola dell'IQR e i limiti di Tukey, non risultano città con prezzo anomalo. Ciò conferma quanto osservato nell'esercizio 7, ovvero che la distribuzione dei prezzi è abbastanza omogenea e priva di valori estremi.
A13: FANO | B13: 120 | C13: =IF(OR(B13<$M$5,B13>$M$4),"OUTLIER"," ") | D13: =IF(COUNTIFS(Tabella1[Città], A13, Tabella1[Categoria],"ALLOGGI AGRITURISTICI")>0,"SI","NO") -> SI | E13: =IF(COUNTIFS(Tabella1[Città], A13, Tabella1[Categoria],"ALBERGHI")>0,"SI","NO") -> SI
A14: FERMIGNANO | B14: 88 | C14: =IF(OR(B14<$M$5,B14>$M$4),"OUTLIER"," ") | D14: =IF(COUNTIFS(Tabella1[Città], A14, Tabella1[Categoria],"ALLOGGI AGRITURISTICI")>0,"SI","NO") -> SI | E14: =IF(COUNTIFS(Tabella1[Città], A14, Tabella1[Categoria],"ALBERGHI")>0,"SI","NO") -> SI
A15: FOSSOMBRONE | B15: 66 | C15: =IF(OR(B15<$M$5,B15>$M$4),"OUTLIER"," ") | D15: =IF(COUNTIFS(Tabella1[Città], A15, Tabella1[Categoria],"ALLOGGI AGRITURISTICI")>0,"SI","NO") -> SI | E15: =IF(COUNTIFS(Tabella1[Città], A15, Tabella1[Categoria],"ALBERGHI")>0,"SI","NO") -> SI | F15: Esercizio 15
A16: FRATTE ROSA | B16: 119 | C16: =IF(OR(B16<$M$5,B16>$M$4),"OUTLIER"," ") | D16: =IF(COUNTIFS(Tabella1[Città], A16, Tabella1[Categoria],"ALLOGGI AGRITURISTICI")>0,"SI","NO") -> SI | E16: =IF(COUNTIFS(Tabella1[Città], A16, Tabella1[Categoria],"ALBERGHI")>0,"SI","NO") -> SI | F16: Prezzo medio città con alberghi: | H16: =AVERAGEIFS(prezzi__2[PREZZO MEDIO],D2:D235,"SI") -> 73.041237 | J16: Il prezzo medio delle città con alberghi e quello con agriturismi sono moltosimili tra loro, con una differenza di appena 0,38€. Questo suggerisce che la presenza di alberghi o agriturismi in una città non influenza in modo significativo il prezzo medio delle strutture ricettive. L'ipotesi nulla sembra essere confermata dai dati.
A17: FRONTINO | B17: 52 | C17: =IF(OR(B17<$M$5,B17>$M$4),"OUTLIER"," ") | D17: =IF(COUNTIFS(Tabella1[Città], A17, Tabella1[Categoria],"ALLOGGI AGRITURISTICI")>0,"SI","NO") -> SI | E17: =IF(COUNTIFS(Tabella1[Città], A17, Tabella1[Categoria],"ALBERGHI")>0,"SI","NO") -> SI | F17: Prezzo medio città con agriturismi: | H17: =AVERAGEIFS(prezzi__2[PREZZO MEDIO],E2:E235,"SI") -> 72.655844
A18: FRONTONE | B18: 75 | C18: =IF(OR(B18<$M$5,B18>$M$4),"OUTLIER"," ") | D18: =IF(COUNTIFS(Tabella1[Città], A18, Tabella1[Categoria],"ALLOGGI AGRITURISTICI")>0,"SI","NO") -> SI | E18: =IF(COUNTIFS(Tabella1[Città], A18, Tabella1[Categoria],"ALBERGHI")>0,"SI","NO") -> SI
A19: GABICCE MARE | B19: 112 | C19: =IF(OR(B19<$M$5,B19>$M$4),"OUTLIER"," ") | D19: =IF(COUNTIFS(Tabella1[Città], A19, Tabella1[Categoria],"ALLOGGI AGRITURISTICI")>0,"SI","NO") -> NO | E19: =IF(COUNTIFS(Tabella1[Città], A19, Tabella1[Categoria],"ALBERGHI")>0,"SI","NO") -> SI
A20: GRADARA | B20: 87 | C20: =IF(OR(B20<$M$5,B20>$M$4),"OUTLIER"," ") | D20: =IF(COUNTIFS(Tabella1[Città], A20, Tabella1[Categoria],"ALLOGGI AGRITURISTICI")>0,"SI","NO") -> NO | E20: =IF(COUNTIFS(Tabella1[Città], A20, Tabella1[Categoria],"ALBERGHI")>0,"SI","NO") -> SI
A21: ISOLA DEL PIANO | B21: 46 | C21: =IF(OR(B21<$M$5,B21>$M$4),"OUTLIER"," ") | D21: =IF(COUNTIFS(Tabella1[Città], A21, Tabella1[Categoria],"ALLOGGI AGRITURISTICI")>0,"SI","NO") -> SI | E21: =IF(COUNTIFS(Tabella1[Città], A21, Tabella1[Categoria],"ALBERGHI")>0,"SI","NO") -> NO
A22: LUNANO | B22: 36 | C22: =IF(OR(B22<$M$5,B22>$M$4),"OUTLIER"," ") | D22: =IF(COUNTIFS(Tabella1[Città], A22, Tabella1[Categoria],"ALLOGGI AGRITURISTICI")>0,"SI","NO") -> SI | E22: =IF(COUNTIFS(Tabella1[Città], A22, Tabella1[Categoria],"ALBERGHI")>0,"SI","NO") -> NO
A23: MACERATA FELTRIA | B23: 32 | C23: =IF(OR(B23<$M$5,B23>$M$4),"OUTLIER"," ") | D23: =IF(COUNTIFS(Tabella1[Città], A23, Tabella1[Categoria],"ALLOGGI AGRITURISTICI")>0,"SI","NO") -> SI | E23: =IF(COUNTIFS(Tabella1[Città], A23, Tabella1[Categoria],"ALBERGHI")>0,"SI","NO") -> SI
A24: MERCATELLO SUL METAURO | B24: 85 | C24: =IF(OR(B24<$M$5,B24>$M$4),"OUTLIER"," ") | D24: =IF(COUNTIFS(Tabella1[Città], A24, Tabella1[Categoria],"ALLOGGI AGRITURISTICI")>0,"SI","NO") -> SI | E24: =IF(COUNTIFS(Tabella1[Città], A24, Tabella1[Categoria],"ALBERGHI")>0,"SI","NO") -> NO
A25: MERCATINO CONCA | B25: 120 | C25: =IF(OR(B25<$M$5,B25>$M$4),"OUTLIER"," ") | D25: =IF(COUNTIFS(Tabella1[Città], A25, Tabella1[Categoria],"ALLOGGI AGRITURISTICI")>0,"SI","NO") -> SI | E25: =IF(COUNTIFS(Tabella1[Città], A25, Tabella1[Categoria],"ALBERGHI")>0,"SI","NO") -> NO
A26: MOMBAROCCIO | B26: 39 | C26: =IF(OR(B26<$M$5,B26>$M$4),"OUTLIER"," ") | D26: =IF(COUNTIFS(Tabella1[Città], A26, Tabella1[Categoria],"ALLOGGI AGRITURISTICI")>0,"SI","NO") -> SI | E26: =IF(COUNTIFS(Tabella1[Città], A26, Tabella1[Categoria],"ALBERGHI")>0,"SI","NO") -> NO
A27: MONDAVIO | B27: 116 | C27: =IF(OR(B27<$M$5,B27>$M$4),"OUTLIER"," ") | D27: =IF(COUNTIFS(Tabella1[Città], A27, Tabella1[Categoria],"ALLOGGI AGRITURISTICI")>0,"SI","NO") -> SI | E27: =IF(COUNTIFS(Tabella1[Città], A27, Tabella1[Categoria],"ALBERGHI")>0,"SI","NO") -> SI
A28: MONDOLFO | B28: 64 | C28: =IF(OR(B28<$M$5,B28>$M$4),"OUTLIER"," ") | D28: =IF(COUNTIFS(Tabella1[Città], A28, Tabella1[Categoria],"ALLOGGI AGRITURISTICI")>0,"SI","NO") -> NO | E28: =IF(COUNTIFS(Tabella1[Città], A28, Tabella1[Categoria],"ALBERGHI")>0,"SI","NO") -> SI
A29: MONTECALVO IN FOGLIA | B29: 46 | C29: =IF(OR(B29<$M$5,B29>$M$4),"OUTLIER"," ") | D29: =IF(COUNTIFS(Tabella1[Città], A29, Tabella1[Categoria],"ALLOGGI AGRITURISTICI")>0,"SI","NO") -> SI | E29: =IF(COUNTIFS(Tabella1[Città], A29, Tabella1[Categoria],"ALBERGHI")>0,"SI","NO") -> NO
... A235: TORRE SAN PATRIZIO | B235: 50 | C235: =IF(OR(B235<$M$5,B235>$M$4),"OUTLIER"," ") | D235: =IF(COUNTIFS(Tabella1[Città], A235, Tabella1[Categoria],"ALLOGGI AGRITURISTICI")>0,"SI","NO") -> SI | E235: =IF(COUNTIFS(Tabella1[Città], A235, Tabella1[Categoria],"ALBERGHI")>0,"SI","NO") -> NO

Sheet Output riepilogo
A1: OUTPUT RIEPILOGO
A3: Statistica della regressione | J3: Prezzo previsto | K3: =B17-B18*('Output riepilogo'!B8) -> 78.714744
A4: R multiplo | B4: 0.037066971 | J4: Il modello di regressione mostra un Rquadrato molto basso, il che significa che il numero di strutture spiega solo lo 0,14% della variabilità del prezzo medio. La significatività e il p value della variabile X1 sono entrambi ben sopra la soglia critica del 5%. Il numero di strutturer presenti in una città non è un buon predittore del suo prezzo medio.
A5: R al quadrato | B5: 0.0013739603
A6: R al quadrato corretto | B6: -0.0029304623
A7: Errore standard | B7: 27.559345
A8: Osservazioni | B8: 234
A10: ANALISI VARIANZA | J10: Esercizio 18
B11: gdl | C11: SQ | D11: MQ | E11: F | F11: Significatività F | J11: Prezzo previsto Pesaro | K11: =74.03+(-0.02*158) -> 70.87
A12: Regressione | B12: 1 | C12: 242.43598 | D12: 242.43598 | E12: 0.31919736 | F12: 0.5726363 | J12: Il modello stima un prezzo medio di 70,87€ per la città di Pesaro. Tuttavia questa previsione è affidabile solo per i valori del numero di strutture di Pesaro.
A13: Residuo | B13: 232 | C13: 176208.06 | D13: 759.51752
A14: Totale | B14: 233 | C14: 176450.5
B16: Coefficienti | C16: Errore standard | D16: Stat t | E16: Valore di significatività | F16: Inferiore 95% | G16: Superiore 95% | H16: Inferiore 95,0% | I16: Superiore 95,0%
A17: Intercetta | B17: 74.034629 | C17: 2.0350084 | D17: 36.380503 | E17: 7.7952677e-98 | F17: 70.02517 | G17: 78.044087 | H17: 70.02517 | I17: 78.044087
A18: Variabile X 1 | B18: -0.020000494 | C18: 0.035400637 | D18: -0.56497554 | E18: 0.5726363 | F18: -0.089748313 | G18: 0.049747325 | H18: -0.089748313 | I18: 0.049747325
